<?xml version='1.0'?>
<sdf version='1.7'>
<model name='hexacopter_unified'>
  <link name='base_link'>
    <pose>0 0 0.1483 0 0 0</pose> 
    <inertial>
      <mass>2</mass>
      <inertia>
        <ixx>0.08</ixx> 
        <ixy>0.0</ixy>  
        <ixz>0.0</ixz>
        <iyy>0.08</iyy>
        <iyz>0.0</iyz>
        <izz>0.16</izz> 
      </inertia>
    </inertial>

    <visual name='visual_box'>
      <pose>0 0 0.0017 0 0 0</pose> 
      <geometry><box><size>0.2 0.2 0.05</size></box></geometry>
      <material><ambient>0.7 0.7 0.7 1</ambient><diffuse>0.7 0.7 0.7 1</diffuse></material>
    </visual>
    <collision name='collision_box'>
      <pose>0 0 0.0017 0 0 0</pose>
      <geometry><box><size>0.2 0.2 0.05</size></box></geometry>
    </collision>

    <visual name='arm1_visual'>
      <pose>0.1948 0.1125 0.0017 0 1.5708 0.5236</pose>
      <geometry><cylinder><radius>0.01</radius><length>0.25</length></cylinder></geometry>
      <material><ambient>0.3 0.3 0.8 1</ambient><diffuse>0.3 0.3 0.8 1</diffuse></material>
    </visual>
    <visual name='arm2_visual'>
      <pose>0 0.225 0.0017 0 1.5708 1.5708</pose>
      <geometry><cylinder><radius>0.01</radius><length>0.25</length></cylinder></geometry>
      <material><ambient>0.3 0.3 0.8 1</ambient><diffuse>0.3 0.3 0.8 1</diffuse></material>
    </visual>
    <visual name='arm3_visual'>
      <pose>-0.1948 0.1125 0.0017 0 1.5708 2.618</pose>
      <geometry><cylinder><radius>0.01</radius><length>0.25</length></cylinder></geometry>
      <material><ambient>0.3 0.3 0.8 1</ambient><diffuse>0.3 0.3 0.8 1</diffuse></material>
    </visual>
    <visual name='arm4_visual'>
      <pose>-0.1948 -0.1125 0.0017 0 1.5708 -2.618</pose>
      <geometry><cylinder><radius>0.01</radius><length>0.25</length></cylinder></geometry>
      <material><ambient>0.3 0.3 0.8 1</ambient><diffuse>0.3 0.3 0.8 1</diffuse></material>
    </visual>
    <visual name='arm5_visual'>
      <pose>0 -0.225 0.0017 0 1.5708 -1.5708</pose>
      <geometry><cylinder><radius>0.01</radius><length>0.25</length></cylinder></geometry>
      <material><ambient>0.3 0.3 0.8 1</ambient><diffuse>0.3 0.3 0.8 1</diffuse></material>
    </visual>
    <visual name='arm6_visual'>
      <pose>0.1948 -0.1125 0.0017 0 1.5708 -0.5236</pose>
      <geometry><cylinder><radius>0.01</radius><length>0.25</length></cylinder></geometry>
      <material><ambient>0.3 0.3 0.8 1</ambient><diffuse>0.3 0.3 0.8 1</diffuse></material>
    </visual>
    
    <visual name='support1_cylinder_visual'>
      <pose>-0.05 0 -0.075 0 0 0</pose> 
      <geometry><cylinder><radius>0.01</radius><length>0.10</length></cylinder></geometry>
      <material><ambient>0.5 0.5 0.5 1</ambient><diffuse>0.5 0.5 0.5 1</diffuse></material>
    </visual>
    <visual name='support1_foot_visual'>
      <pose>-0.05 0 -0.130 0 0 0</pose>
      <geometry><box><size>0.05 0.05 0.01</size></box></geometry>
      <material><ambient>0.3 0.3 0.8 1</ambient><diffuse>0.3 0.3 0.8 1</diffuse></material> 
    </visual>
    
    <visual name='support2_cylinder_visual'>
      <pose>0.05 0 -0.075 0 0 0</pose>
      <geometry><cylinder><radius>0.01</radius><length>0.10</length></cylinder></geometry>
      <material><ambient>0.5 0.5 0.5 1</ambient><diffuse>0.5 0.5 0.5 1</diffuse></material>
    </visual>
    <visual name='support2_foot_visual'>
      <pose>0.05 0 -0.130 0 0 0</pose>
      <geometry><box><size>0.05 0.05 0.01</size></box></geometry>
      <material><ambient>0.3 0.3 0.8 1</ambient><diffuse>0.3 0.3 0.8 1</diffuse></material> 
    </visual>

    <collision name='support1_collision'>
      <pose>-0.05 0 -0.075 0 0 0</pose>
      <geometry><cylinder><radius>0.01</radius><length>0.10</length></cylinder></geometry>
    </collision>
    <collision name='support2_collision'>
      <pose>0.05 0 -0.075 0 0 0</pose>
      <geometry><cylinder><radius>0.01</radius><length>0.10</length></cylinder></geometry>
    </collision>
    
    <sensor name="air_pressure_sensor" type="air_pressure">
        <always_on>1</always_on>
        <update_rate>50</update_rate>
        <air_pressure>
          <!-- Noise modeled after BMP390 -->
          <pressure>
            <noise type="gaussian">
              <mean>0</mean>
              <stddev>3</stddev>
            </noise>
          </pressure>
        </air_pressure>
      </sensor>
      <sensor name="magnetometer_sensor" type="magnetometer">
        <always_on>1</always_on>
        <update_rate>100</update_rate>
        <magnetometer>
          <!-- TODO: update to fix units and coordinate system when we move past Harmonic -->
          <!-- See https://github.com/gazebosim/gz-sim/pull/2460 -->
          <!-- 3mgauss RMS: NOTE: noise is in tesla but sensor reports data in gauss -->
          <!-- Noise modeled after IIS2MDC -->
          <x>
            <noise type="gaussian">
              <stddev>0.0001</stddev>
            </noise>
          </x>
          <y>
            <noise type="gaussian">
              <stddev>0.0001</stddev>
            </noise>
          </y>
          <z>
            <noise type="gaussian">
              <stddev>0.0001</stddev>
            </noise>
          </z>
        </magnetometer>
      </sensor>
      <sensor name="imu_sensor" type="imu">
        <always_on>1</always_on>
        <update_rate>250</update_rate>
        <imu>
          <angular_velocity>
            <!-- Noise modeled after IIM42653 -->
            <!-- 0.05 deg/s converted to rad/s -->
            <x>
              <noise type="gaussian">
                <mean>0.0</mean>
                <stddev>0.0008726646</stddev>
              </noise>
            </x>
            <y>
              <noise type="gaussian">
                <mean>0.0</mean>
                <stddev>0.0008726646</stddev>
              </noise>
            </y>
            <z>
              <noise type="gaussian">
                <mean>0.0</mean>
                <stddev>0.0008726646</stddev>
              </noise>
            </z>
          </angular_velocity>
          <linear_acceleration>
            <!-- Noise modeled after IIM42653 -->
            <!-- X & Y axis: 0.65 mg-rms converted to m/ss -->
            <x>
              <noise type="gaussian">
                <mean>0.0</mean>
                <stddev>0.00637</stddev>
              </noise>
            </x>
            <y>
              <noise type="gaussian">
                <mean>0.0</mean>
                <stddev>0.00637</stddev>
              </noise>
            </y>
            <!-- Z axis: 0.70 mg-rms converted to m/ss-->
            <z>
              <noise type="gaussian">
                <mean>0.0</mean>
                <stddev>0.00686</stddev>
              </noise>
            </z>
          </linear_acceleration>
        </imu>
      </sensor>
      <sensor name="navsat_sensor" type="navsat">
        <always_on>1</always_on>
        <update_rate>30</update_rate>
      </sensor>
    
  </link>
  
  <link name="rotor_0">
      <gravity>true</gravity>
      <self_collide>false</self_collide>
      <velocity_decay/>
      <pose>0.30305 0.1750 0.18 0 0 0</pose>
      <inertial>
          <mass>0.016076923076923075</mass>
          <inertia>
            <ixx>3.8464910483993325e-07</ixx>
            <iyy>2.6115851691700804e-05</iyy>
            <izz>2.649858234714004e-05</izz>
          </inertia>
        </inertial>
      <visual name="rotor_0_visual">
        <pose>-0.022 -0.14638461538461536 -0.016 0 0 0</pose>
        <geometry>
          <mesh>
            <scale>0.8461538461538461 0.8461538461538461 0.8461538461538461</scale>
            <uri>model://x500_base/meshes/1345_prop_ccw.stl</uri>
          </mesh>
        </geometry>
        <material>
          <script>
            <name>Gazebo/DarkGrey</name>
            <uri>file://media/materials/scripts/gazebo.material</uri>
          </script>
        </material>
      </visual>
      <visual name="rotor_0_visual_motor_bell">
        <pose>0 0 -.032 0 0 0</pose>
        <geometry>
          <mesh>
            <scale>1 1 1</scale>
            <uri>model://x500_base/meshes/5010Bell.dae</uri>
          </mesh>
        </geometry>
      </visual>
      <collision name="rotor_0_collision">
        <pose>0 0 0 0 0 0 </pose>
        <geometry>
          <box>
            <size>0.2792307692307692 0.016923076923076923 0.0008461538461538462</size>
          </box>
        </geometry>
        <surface>
          <contact>
            <ode>
              <min_depth>0.001</min_depth>
              <max_vel>0</max_vel>
            </ode>
          </contact>
          <friction>
            <ode/>
          </friction>
        </surface>
      </collision>
    </link>
    <joint name="rotor_0_joint" type="revolute">
      <parent>base_link</parent>
      <child>rotor_0</child>
      <axis>
        <xyz>0 0 1</xyz>
        <limit>
          <lower>-1e+16</lower>
          <upper>1e+16</upper>
        </limit>
        <dynamics>
          <spring_reference>0</spring_reference>
          <spring_stiffness>0</spring_stiffness>
        </dynamics>
      </axis>
    </joint>
    
     <link name="rotor_1">
      <gravity>true</gravity>
      <self_collide>false</self_collide>
      <velocity_decay/>
      <pose>0.000 0.350 0.18 0 0 0</pose>
      <inertial>
          <mass>0.016076923076923075</mass>
          <inertia>
            <ixx>3.8464910483993325e-07</ixx>
            <iyy>2.6115851691700804e-05</iyy>
            <izz>2.649858234714004e-05</izz>
          </inertia>
        </inertial>
      <visual name="rotor_1_visual">
        <pose>-0.022 -0.14638461538461536 -0.016 0 0 0</pose>
        <geometry>
          <mesh>
            <scale>0.8461538461538461 0.8461538461538461 0.8461538461538461</scale>
            <uri>model://x500_base/meshes/1345_prop_cw.stl</uri>
          </mesh>
        </geometry>
        <material>
          <script>
            <name>Gazebo/DarkGrey</name>
            <uri>file://media/materials/scripts/gazebo.material</uri>
          </script>
        </material>
      </visual>
      <visual name="rotor_1_visual_motor_top">
        <pose>0 0 -.032 0 0 0</pose>
        <geometry>
          <mesh>
            <scale>1 1 1</scale>
            <uri>model://x500_base/meshes/5010Bell.dae</uri>
          </mesh>
        </geometry>
      </visual>
      <collision name="rotor_1_collision">
        <pose>0 0 0 0 0 0 </pose>
        <geometry>
          <box>
            <size>0.2792307692307692 0.016923076923076923 0.0008461538461538462</size>
          </box>
        </geometry>
        <surface>
          <contact>
            <ode>
              <min_depth>0.001</min_depth>
              <max_vel>0</max_vel>
            </ode>
          </contact>
          <friction>
            <ode/>
          </friction>
        </surface>
      </collision>
    </link>
    <joint name="rotor_1_joint" type="revolute">
      <parent>base_link</parent>
      <child>rotor_1</child>
      <axis>
        <xyz>0 0 1</xyz>
        <limit>
          <lower>-1e+16</lower>
          <upper>1e+16</upper>
        </limit>
        <dynamics>
          <spring_reference>0</spring_reference>
          <spring_stiffness>0</spring_stiffness>
        </dynamics>
      </axis>
    </joint>
    
    <link name="rotor_2">
      <gravity>true</gravity>
      <self_collide>false</self_collide>
      <velocity_decay/>
      <pose>-0.30305 0.1750 0.18 0 0 0</pose>
      <inertial>
          <mass>0.016076923076923075</mass>
          <inertia>
            <ixx>3.8464910483993325e-07</ixx>
            <iyy>2.6115851691700804e-05</iyy>
            <izz>2.649858234714004e-05</izz>
          </inertia>
        </inertial>
      <visual name="rotor_2_visual">
        <pose>-0.022 -0.14638461538461536 -0.016 0 0 0</pose>
        <geometry>
          <mesh>
            <scale>0.8461538461538461 0.8461538461538461 0.8461538461538461</scale>
            <uri>model://x500_base/meshes/1345_prop_ccw.stl</uri>
          </mesh>
        </geometry>
        <material>
          <script>
            <name>Gazebo/DarkGrey</name>
            <uri>file://media/materials/scripts/gazebo.material</uri>
          </script>
        </material>
      </visual>
      <visual name="rotor_2_visual_motor_top">
        <pose>0 0 -.032 0 0 0</pose>
        <geometry>
          <mesh>
            <scale>1 1 1</scale>
            <uri>model://x500_base/meshes/5010Bell.dae</uri>
          </mesh>
        </geometry>
      </visual>
      <collision name="rotor_2_collision">
        <pose>0 0 0 0 0 0 </pose>
        <geometry>
          <box>
            <size>0.2792307692307692 0.016923076923076923 0.0008461538461538462</size>
          </box>
        </geometry>
        <surface>
          <contact>
            <ode>
              <min_depth>0.001</min_depth>
              <max_vel>0</max_vel>
            </ode>
          </contact>
          <friction>
            <ode/>
          </friction>
        </surface>
      </collision>
    </link>
    <joint name="rotor_2_joint" type="revolute">
      <parent>base_link</parent>
      <child>rotor_2</child>
      <axis>
        <xyz>0 0 1</xyz>
        <limit>
          <lower>-1e+16</lower>
          <upper>1e+16</upper>
        </limit>
        <dynamics>
          <spring_reference>0</spring_reference>
          <spring_stiffness>0</spring_stiffness>
        </dynamics>
      </axis>
    </joint>
    
    <link name="rotor_3">
      <gravity>true</gravity>
      <self_collide>false</self_collide>
      <velocity_decay/>
      <pose>-0.30305 -0.1750 0.18 0 0 0</pose>
      <inertial>
          <mass>0.016076923076923075</mass>
          <inertia>
            <ixx>3.8464910483993325e-07</ixx>
            <iyy>2.6115851691700804e-05</iyy>
            <izz>2.649858234714004e-05</izz>
          </inertia>
        </inertial>
      <visual name="rotor_3_visual">
        <pose>-0.022 -0.14638461538461536 -0.016 0 0 0</pose>
        <geometry>
          <mesh>
            <scale>0.8461538461538461 0.8461538461538461 0.8461538461538461</scale>
            <uri>model://x500_base/meshes/1345_prop_cw.stl</uri>
          </mesh>
        </geometry>
        <material>
          <script>
            <name>Gazebo/DarkGrey</name>
            <uri>file://media/materials/scripts/gazebo.material</uri>
          </script>
        </material>
      </visual>
      <visual name="rotor_3_visual_motor_top">
        <pose>0 0 -.032 0 0 0</pose>
        <geometry>
          <mesh>
            <scale>1 1 1</scale>
            <uri>model://x500_base/meshes/5010Bell.dae</uri>
          </mesh>
        </geometry>
      </visual>
      <collision name="rotor_3_collision">
        <pose>0 0 0 0 0 0 </pose>
        <geometry>
          <box>
            <size>0.2792307692307692 0.016923076923076923 0.0008461538461538462</size>
          </box>
        </geometry>
        <surface>
          <contact>
            <ode>
              <min_depth>0.001</min_depth>
              <max_vel>0</max_vel>
            </ode>
          </contact>
          <friction>
            <ode/>
          </friction>
        </surface>
      </collision>
    </link>
    <joint name="rotor_3_joint" type="revolute">
      <parent>base_link</parent>
      <child>rotor_3</child>
      <axis>
        <xyz>0 0 1</xyz>
        <limit>
          <lower>-1e+16</lower>
          <upper>1e+16</upper>
        </limit>
        <dynamics>
          <spring_reference>0</spring_reference>
          <spring_stiffness>0</spring_stiffness>
        </dynamics>
      </axis>
    </joint>
    
    <link name="rotor_4">
      <gravity>true</gravity>
      <self_collide>false</self_collide>
      <velocity_decay/>
      <pose>0.000 -0.350 0.18 0 0 0</pose>
      <inertial>
          <mass>0.016076923076923075</mass>
          <inertia>
            <ixx>3.8464910483993325e-07</ixx>
            <iyy>2.6115851691700804e-05</iyy>
            <izz>2.649858234714004e-05</izz>
          </inertia>
        </inertial>
      <visual name="rotor_4_visual">
        <pose>-0.022 -0.14638461538461536 -0.016 0 0 0</pose>
        <geometry>
          <mesh>
            <scale>0.8461538461538461 0.8461538461538461 0.8461538461538461</scale>
            <uri>model://x500_base/meshes/1345_prop_ccw.stl</uri>
          </mesh>
        </geometry>
        <material>
          <script>
            <name>Gazebo/DarkGrey</name>
            <uri>file://media/materials/scripts/gazebo.material</uri>
          </script>
        </material>
      </visual>
      <visual name="rotor_4_visual_motor_top">
        <pose>0 0 -.032 0 0 0</pose>
        <geometry>
          <mesh>
            <scale>1 1 1</scale>
            <uri>model://x500_base/meshes/5010Bell.dae</uri>
          </mesh>
        </geometry>
      </visual>
      <collision name="rotor_4_collision">
        <pose>0 0 0 0 0 0 </pose>
        <geometry>
          <box>
            <size>0.2792307692307692 0.016923076923076923 0.0008461538461538462</size>
          </box>
        </geometry>
        <surface>
          <contact>
            <ode>
              <min_depth>0.001</min_depth>
              <max_vel>0</max_vel>
            </ode>
          </contact>
          <friction>
            <ode/>
          </friction>
        </surface>
      </collision>
    </link>
    <joint name="rotor_4_joint" type="revolute">
      <parent>base_link</parent>
      <child>rotor_4</child>
      <axis>
        <xyz>0 0 1</xyz>
        <limit>
          <lower>-1e+16</lower>
          <upper>1e+16</upper>
        </limit>
        <dynamics>
          <spring_reference>0</spring_reference>
          <spring_stiffness>0</spring_stiffness>
        </dynamics>
      </axis>
    </joint>
    
    <link name="rotor_5">
      <gravity>true</gravity>
      <self_collide>false</self_collide>
      <velocity_decay/>
      <pose>0.30305 -0.1750 0.18 0 0 0</pose>
      <inertial>
          <mass>0.016076923076923075</mass>
          <inertia>
            <ixx>3.8464910483993325e-07</ixx>
            <iyy>2.6115851691700804e-05</iyy>
            <izz>2.649858234714004e-05</izz>
          </inertia>
        </inertial>
      <visual name="rotor_5_visual">
        <pose>-0.022 -0.14638461538461536 -0.016 0 0 0</pose>
        <geometry>
          <mesh>
            <scale>0.8461538461538461 0.8461538461538461 0.8461538461538461</scale>
            <uri>model://x500_base/meshes/1345_prop_cw.stl</uri>
          </mesh>
        </geometry>
        <material>
          <script>
            <name>Gazebo/DarkGrey</name>
            <uri>file://media/materials/scripts/gazebo.material</uri>
          </script>
        </material>
      </visual>
      <visual name="rotor_5_visual_motor_top">
        <pose>0 0 -.032 0 0 0</pose>
        <geometry>
          <mesh>
            <scale>1 1 1</scale>
            <uri>model://x500_base/meshes/5010Bell.dae</uri>
          </mesh>
        </geometry>
      </visual>
      <collision name="rotor_5_collision">
        <pose>0 0 0 0 0 0 </pose>
        <geometry>
          <box>
            <size>0.2792307692307692 0.016923076923076923 0.0008461538461538462</size>
          </box>
        </geometry>
        <surface>
          <contact>
            <ode>
              <min_depth>0.001</min_depth>
              <max_vel>0</max_vel>
            </ode>
          </contact>
          <friction>
            <ode/>
          </friction>
        </surface>
      </collision>
    </link>
    <joint name="rotor_5_joint" type="revolute">
      <parent>base_link</parent>
      <child>rotor_5</child>
      <axis>
        <xyz>0 0 1</xyz>
        <limit>
          <lower>-1e+16</lower>
          <upper>1e+16</upper>
        </limit>
        <dynamics>
          <spring_reference>0</spring_reference>
          <spring_stiffness>0</spring_stiffness>
        </dynamics>
      </axis>
    </joint>
  
  	<plugin filename="gz-sim-multicopter-motor-model-system" name="gz::sim::systems::MulticopterMotorModel">
	  
	    
	      <jointName>rotor_0_joint</jointName>
	      <linkName>rotor_0</linkName>
	      <turningDirection>ccw</turningDirection>
	      <timeConstantUp>0.0125</timeConstantUp>
	      <timeConstantDown>0.025</timeConstantDown>
	      <maxRotVelocity>1000.0</maxRotVelocity>
	      <motorConstant>8.54858e-06</motorConstant>
	      <momentConstant>0.016</momentConstant>
	      <commandSubTopic>command/motor_speed</commandSubTopic>
	      <motorNumber>0</motorNumber>
	      <rotorDragCoefficient>8.06428e-05</rotorDragCoefficient>
	      <rollingMomentCoefficient>1e-06</rollingMomentCoefficient>
	      <rotorVelocitySlowdownSim>10</rotorVelocitySlowdownSim>
	      <motorType>velocity</motorType>
	 </plugin>  
	 
	 <plugin filename="gz-sim-multicopter-motor-model-system" name="gz::sim::systems::MulticopterMotorModel">
	   

	    
	      <jointName>rotor_1_joint</jointName>
	      <linkName>rotor_1</linkName>
	      <turningDirection>cw</turningDirection>
	      <timeConstantUp>0.0125</timeConstantUp>
	      <timeConstantDown>0.025</timeConstantDown>
	      <maxRotVelocity>1000.0</maxRotVelocity>
	      <motorConstant>8.54858e-06</motorConstant>
	      <momentConstant>0.016</momentConstant>
	      <commandSubTopic>command/motor_speed</commandSubTopic>
	      <motorNumber>1</motorNumber>
	      <rotorDragCoefficient>8.06428e-05</rotorDragCoefficient>
	      <rollingMomentCoefficient>1e-06</rollingMomentCoefficient>
	      <rotorVelocitySlowdownSim>10</rotorVelocitySlowdownSim>
	      <motorType>velocity</motorType>
	    
          </plugin>
          
          <plugin filename="gz-sim-multicopter-motor-model-system" name="gz::sim::systems::MulticopterMotorModel">
	  
	   
	      <jointName>rotor_2_joint</jointName>
	      <linkName>rotor_2</linkName>
	      <turningDirection>ccw</turningDirection>
	      <timeConstantUp>0.0125</timeConstantUp>
	      <timeConstantDown>0.025</timeConstantDown>
	      <maxRotVelocity>1000.0</maxRotVelocity>
	      <motorConstant>8.54858e-06</motorConstant>
	      <momentConstant>0.016</momentConstant>
	      <commandSubTopic>command/motor_speed</commandSubTopic>
	      <motorNumber>2</motorNumber>
	      <rotorDragCoefficient>8.06428e-05</rotorDragCoefficient>
	      <rollingMomentCoefficient>1e-06</rollingMomentCoefficient>
	      <rotorVelocitySlowdownSim>10</rotorVelocitySlowdownSim>
	      <motorType>velocity</motorType>
	  </plugin>

          <plugin filename="gz-sim-multicopter-motor-model-system" name="gz::sim::systems::MulticopterMotorModel">
	  
	      <jointName>rotor_3_joint</jointName>
	      <linkName>rotor_3</linkName>
	      <turningDirection>cw</turningDirection>
	      <timeConstantUp>0.0125</timeConstantUp>
	      <timeConstantDown>0.025</timeConstantDown>
	      <maxRotVelocity>1000.0</maxRotVelocity>
	      <motorConstant>8.54858e-06</motorConstant>
	      <momentConstant>0.016</momentConstant>
	      <commandSubTopic>command/motor_speed</commandSubTopic>
	      <motorNumber>3</motorNumber>
	      <rotorDragCoefficient>8.06428e-05</rotorDragCoefficient>
	      <rollingMomentCoefficient>1e-06</rollingMomentCoefficient>
	      <rotorVelocitySlowdownSim>10</rotorVelocitySlowdownSim>
	      <motorType>velocity</motorType>
	    
          </plugin>
          
          <plugin filename="gz-sim-multicopter-motor-model-system" name="gz::sim::systems::MulticopterMotorModel">
	  
	      <jointName>rotor_4_joint</jointName>
	      <linkName>rotor_4</linkName>
	      <turningDirection>ccw</turningDirection>
	      <timeConstantUp>0.0125</timeConstantUp>
	      <timeConstantDown>0.025</timeConstantDown>
	      <maxRotVelocity>1000.0</maxRotVelocity>
	      <motorConstant>8.54858e-06</motorConstant>
	      <momentConstant>0.016</momentConstant>
	      <commandSubTopic>command/motor_speed</commandSubTopic>
	      <motorNumber>4</motorNumber>
	      <rotorDragCoefficient>8.06428e-05</rotorDragCoefficient>
	      <rollingMomentCoefficient>1e-06</rollingMomentCoefficient>
	      <rotorVelocitySlowdownSim>10</rotorVelocitySlowdownSim>
	      <motorType>velocity</motorType>
	  </plugin>
	  	    
          <plugin filename="gz-sim-multicopter-motor-model-system" name="gz::sim::systems::MulticopterMotorModel">
	  
	      <jointName>rotor_5_joint</jointName>
	      <linkName>rotor_5</linkName>
	      <turningDirection>cw</turningDirection>
	      <timeConstantUp>0.0125</timeConstantUp>
	      <timeConstantDown>0.025</timeConstantDown>
	      <maxRotVelocity>1000.0</maxRotVelocity>
	      <motorConstant>8.54858e-06</motorConstant>
	      <momentConstant>0.016</momentConstant>
	      <commandSubTopic>command/motor_speed</commandSubTopic>
	      <motorNumber>5</motorNumber>
	      <rotorDragCoefficient>8.06428e-05</rotorDragCoefficient>
	      <rollingMomentCoefficient>1e-06</rollingMomentCoefficient>
	      <rotorVelocitySlowdownSim>10</rotorVelocitySlowdownSim>
	      <motorType>velocity</motorType>
	  </plugin> 
 </model>
</sdf>
